Workbook

Sheet worker file
A1: ID | B1: Dept | C1: Location | D1: State | E1: Country | F1: Level | G1: FLSA | H1: Pay Rate type | I1: Salary | J1: Hourly rate | K1: Currency | L1: Pay Group | M1: Hire Date | N1: Term Date | O1: Leave Start Date | P1: Mgr | Q1: Status | R1: Worker Type | S1: scheduled weekly hours | T1: time type | U1: time entry template | V1: time calculation group | W1: work schedule | X1: Default Shift Code | Y1: Notes
A2: E0001 | B2: GPU Cloud | C2: San Francisco | D2: CA | E2: US | F2: M5 | G2: Exempt | H2: Salary | I2: 285,000 | K2: USD | L2: US Semi-monthly | M2: 44635 | P2: E0000 | Q2: Active | R2: Employee | S2: 40 | T2: Full time | U2: =IF(AND(TRIM(E2)="US",TRIM(G2)="Non-Exempt"),"US Non-Exempt EEs","") | V2: =IF(AND(TRIM(E2)="US",TRIM(G2)="Non-Exempt"),IF(TRIM(D2)="CA","US California Non-Exempt","US Non-California Non-Exempt"),"") | W2: =_xlfn.XLOOKUP(X2,ShiftCodes[Code],ShiftCodes[Work Schedule],"Unknown code") -> Standard (Mon–Fri 9:00–17:30) | X2: STD
A3: E0004 | B3: GPU Cloud | C3: Remote-US | D3: WA | E3: US | F3: IC3 | G3: Exempt | H3: Salary | I3: 160,000 | K3: USD | L3: US Semi-monthly | M3: 45158 | N3: 46326 | P3: E0002 | Q3: Termination pending | R3: Employee | S3: 40 | T3: Full time | U3: =IF(AND(TRIM(E3)="US",TRIM(G3)="Non-Exempt"),"US Non-Exempt EEs","") | V3: =IF(AND(TRIM(E3)="US",TRIM(G3)="Non-Exempt"),IF(TRIM(D3)="CA","US California Non-Exempt","US Non-California Non-Exempt"),"") | W3: =_xlfn.XLOOKUP(X3,ShiftCodes[Code],ShiftCodes[Work Schedule],"Unknown code") -> Standard (Mon–Fri 9:00–17:30) | X3: STD | Y3: Term date = end of current pay period (US Semi-monthly Oct 16–31, 2026)
A4: E0006 | B4: On-Prem | C4: London | D4: UK | E4: UK | F4: IC4 | G4: Exempt | H4: Salary | I4: 85,000 | K4: GBP | L4: UK Monthly | M4: 45340 | N4: 46326 | P4: E0005 | Q4: Termination pending | R4: Employee | S4: 37.5 | T4: Full time | U4: =IF(AND(TRIM(E4)="US",TRIM(G4)="Non-Exempt"),"US Non-Exempt EEs","") | V4: =IF(AND(TRIM(E4)="US",TRIM(G4)="Non-Exempt"),IF(TRIM(D4)="CA","US California Non-Exempt","US Non-California Non-Exempt"),"") | W4: =_xlfn.XLOOKUP(X4,ShiftCodes[Code],ShiftCodes[Work Schedule],"Unknown code") -> Standard (Mon–Fri 9:00–17:30) | X4: STD | Y4: Term date = end of current pay period (UK Monthly Oct 1–31, 2026)
A5: E0008 | B5: Engineering | C5: Toronto | D5: Ontario | E5: CA | F5: IC5 | G5: Exempt | H5: Salary | I5: 225000 | K5: CAD | L5: Canada Monthly | M5: 45019 | P5: E0007 | Q5: Active | R5: Employee | S5: 40 | T5: Full time | U5: =IF(AND(TRIM(E5)="US",TRIM(G5)="Non-Exempt"),"US Non-Exempt EEs","") | V5: =IF(AND(TRIM(E5)="US",TRIM(G5)="Non-Exempt"),IF(TRIM(D5)="CA","US California Non-Exempt","US Non-California Non-Exempt"),"") | W5: =_xlfn.XLOOKUP(X5,ShiftCodes[Code],ShiftCodes[Work Schedule],"Unknown code") -> Standard (Mon–Fri 9:00–17:30) | X5: STD
A6: E0009 | B6: Engineering | C6: Bangalore | D6: Karnataka | E6: IN | F6: IC4 | G6: Exempt | H6: Salary | I6: 45,00,000 | K6: INR | L6: India Monthly | M6: 44948 | N6: 46310 | P6: E0007 | Q6: Termination pending | R6: Employee | S6: 40 | T6: Full time | U6: =IF(AND(TRIM(E6)="US",TRIM(G6)="Non-Exempt"),"US Non-Exempt EEs","") | V6: =IF(AND(TRIM(E6)="US",TRIM(G6)="Non-Exempt"),IF(TRIM(D6)="CA","US California Non-Exempt","US Non-California Non-Exempt"),"") | W6: =_xlfn.XLOOKUP(X6,ShiftCodes[Code],ShiftCodes[Work Schedule],"Unknown code") -> Standard (Mon–Fri 9:00–17:30) | X6: STD | Y6: Term date mid-period (India Monthly Oct 1–31, 2026)
A7: E0021 | B7: On-Prem | C7: San Jose | D7: CA | E7: US | F7: T2 | G7: Non-Exempt | H7: Hourly | J7: 42 | K7: USD | L7: US Biweekly | M7: 45418 | P7: E0005 | Q7: Active | R7: Employee | S7: 40 | T7: Full time | U7: =IF(AND(TRIM(E7)="US",TRIM(G7)="Non-Exempt"),"US Non-Exempt EEs","") -> US Non-Exempt EEs | V7: =IF(AND(TRIM(E7)="US",TRIM(G7)="Non-Exempt"),IF(TRIM(D7)="CA","US California Non-Exempt","US Non-California Non-Exempt"),"") -> US California Non-Exempt | W7: =_xlfn.XLOOKUP(X7,ShiftCodes[Code],ShiftCodes[Work Schedule],"Unknown code") -> Shift A – Day (Mon–Fri 06:00–14:30) | X7: DAY
A8: E0022 | B8: On-Prem | C8: Austin | D8: TX | E8: US | F8: T2 | G8: Non-Exempt | H8: Hourly | J8: 40 | K8: USD | L8: US Biweekly | M8: 45488 | P8: E0005 | Q8: Active | R8: Employee | S8: 40 | T8: Full time | U8: =IF(AND(TRIM(E8)="US",TRIM(G8)="Non-Exempt"),"US Non-Exempt EEs","") -> US Non-Exempt EEs | V8: =IF(AND(TRIM(E8)="US",TRIM(G8)="Non-Exempt"),IF(TRIM(D8)="CA","US California Non-Exempt","US Non-California Non-Exempt"),"") -> US Non-California Non-Exempt | W8: =_xlfn.XLOOKUP(X8,ShiftCodes[Code],ShiftCodes[Work Schedule],"Unknown code") -> Shift B – Swing (Mon–Fri 14:00–22:30) | X8: SWNG
A9: E0148 | B9: GPU Cloud | C9: San Francisco | D9: CA | E9: US | F9: IC3 | G9: Non-Exempt | H9: Hourly | J9: 80 | K9: USD | L9: US Biweekly | M9: 45545 | N9: 46312 | P9: E0002 | Q9: Termination pending | R9: Employee | S9: 40 | T9: Full time | U9: =IF(AND(TRIM(E9)="US",TRIM(G9)="Non-Exempt"),"US Non-Exempt EEs","") -> US Non-Exempt EEs | V9: =IF(AND(TRIM(E9)="US",TRIM(G9)="Non-Exempt"),IF(TRIM(D9)="CA","US California Non-Exempt","US Non-California Non-Exempt"),"") -> US California Non-Exempt | W9: =_xlfn.XLOOKUP(X9,ShiftCodes[Code],ShiftCodes[Work Schedule],"Unknown code") -> Standard (Mon–Fri 9:00–17:30) | X9: STD | Y9: Last day = end of current pay period (US Biweekly Oct 4–17, 2026)
A10: E0149 | B10: G&A | C10: Remote-US | D10: NY | E10: US | F10: IC4 | G10: Exempt | H10: Salary | I10: 180,000 | K10: USD | L10: US Semi-monthly | M10: 45383 | O10: 46297 | P10: E0010 | Q10: On Leave(unpaid) | R10: Employee | S10: 40 | T10: Full time | U10: =IF(AND(TRIM(E10)="US",TRIM(G10)="Non-Exempt"),"US Non-Exempt EEs","") | V10: =IF(AND(TRIM(E10)="US",TRIM(G10)="Non-Exempt"),IF(TRIM(D10)="CA","US California Non-Exempt","US Non-California Non-Exempt"),"") | W10: =_xlfn.XLOOKUP(X10,ShiftCodes[Code],ShiftCodes[Work Schedule],"Unknown code") -> Standard (Mon–Fri 9:00–17:30) | X10: STD
A11: E0203 | B11: Engineering | C11: San Francisco | D11: CA | E11: US | F11: IC4 | G11: Exempt | H11: Salary | I11: 190,000 | K11: USD | L11: US Semi-monthly | M11: 46316 | P11: E0007 | Q11: New Hire | R11: Employee | S11: 40 | T11: Full time | U11: =IF(AND(TRIM(E11)="US",TRIM(G11)="Non-Exempt"),"US Non-Exempt EEs","") | V11: =IF(AND(TRIM(E11)="US",TRIM(G11)="Non-Exempt"),IF(TRIM(D11)="CA","US California Non-Exempt","US Non-California Non-Exempt"),"") | W11: =_xlfn.XLOOKUP(X11,ShiftCodes[Code],ShiftCodes[Work Schedule],"Unknown code") -> Standard (Mon–Fri 9:00–17:30) | X11: STD | Y11: New hire starting mid-period (US Semi-monthly Oct 16–31, 2026)
A12: E0000 | B12: G&A | C12: San Francisco | D12: CA | E12: US | F12: M7 | G12: Exempt | H12: Salary | I12: 383000 | K12: USD | L12: US Semi-monthly | M12: 43472 | Q12: Active | R12: Employee | S12: 40 | T12: Full time | U12: =IF(AND(TRIM(E12)="US",TRIM(G12)="Non-Exempt"),"US Non-Exempt EEs","") | V12: =IF(AND(TRIM(E12)="US",TRIM(G12)="Non-Exempt"),IF(TRIM(D12)="CA","US California Non-Exempt","US Non-California Non-Exempt"),"") | W12: =_xlfn.XLOOKUP(X12,ShiftCodes[Code],ShiftCodes[Work Schedule],"Unknown code") -> Standard (Mon–Fri 9:00–17:30) | X12: STD
A13: E0002 | B13: GPU Cloud | C13: San Francisco | D13: CA | E13: US | F13: M6 | G13: Exempt | H13: Salary | I13: 370000 | K13: USD | L13: US Semi-monthly | M13: 43892 | P13: E0000 | Q13: Active | R13: Employee | S13: 40 | T13: Full time | U13: =IF(AND(TRIM(E13)="US",TRIM(G13)="Non-Exempt"),"US Non-Exempt EEs","") | V13: =IF(AND(TRIM(E13)="US",TRIM(G13)="Non-Exempt"),IF(TRIM(D13)="CA","US California Non-Exempt","US Non-California Non-Exempt"),"") | W13: =_xlfn.XLOOKUP(X13,ShiftCodes[Code],ShiftCodes[Work Schedule],"Unknown code") -> Standard (Mon–Fri 9:00–17:30) | X13: STD
A14: E0003 | B14: GPU Cloud | C14: Seattle | D14: WA | E14: US | F14: M5 | G14: Exempt | H14: Salary | I14: 295000 | K14: USD | L14: US Semi-monthly | M14: 44022 | P14: E0002 | Q14: Active | R14: Employee | S14: 40 | T14: Full time | U14: =IF(AND(TRIM(E14)="US",TRIM(G14)="Non-Exempt"),"US Non-Exempt EEs","") | V14: =IF(AND(TRIM(E14)="US",TRIM(G14)="Non-Exempt"),IF(TRIM(D14)="CA","US California Non-Exempt","US Non-California Non-Exempt"),"") | W14: =_xlfn.XLOOKUP(X14,ShiftCodes[Code],ShiftCodes[Work Schedule],"Unknown code") -> Standard (Mon–Fri 9:00–17:30) | X14: STD
A15: E0005 | B15: On-Prem | C15: Dallas | D15: TX | E15: US | F15: M6 | G15: Exempt | H15: Salary | I15: 345000 | K15: USD | L15: US Semi-monthly | M15: 43983 | P15: E0000 | Q15: Active | R15: Employee | S15: 40 | T15: Full time | U15: =IF(AND(TRIM(E15)="US",TRIM(G15)="Non-Exempt"),"US Non-Exempt EEs","") | V15: =IF(AND(TRIM(E15)="US",TRIM(G15)="Non-Exempt"),IF(TRIM(D15)="CA","US California Non-Exempt","US Non-California Non-Exempt"),"") | W15: =_xlfn.XLOOKUP(X15,ShiftCodes[Code],ShiftCodes[Work Schedule],"Unknown code") -> Standard (Mon–Fri 9:00–17:30) | X15: STD
A16: E0007 | B16: Engineering | C16: Austin | D16: TX | E16: US | F16: M6 | G16: Exempt | H16: Salary | I16: 340000 | K16: USD | L16: US Semi-monthly | M16: 43864 | P16: E0000 | Q16: Active | R16: Employee | S16: 40 | T16: Full time | U16: =IF(AND(TRIM(E16)="US",TRIM(G16)="Non-Exempt"),"US Non-Exempt EEs","") | V16: =IF(AND(TRIM(E16)="US",TRIM(G16)="Non-Exempt"),IF(TRIM(D16)="CA","US California Non-Exempt","US Non-California Non-Exempt"),"") | W16: =_xlfn.XLOOKUP(X16,ShiftCodes[Code],ShiftCodes[Work Schedule],"Unknown code") -> Standard (Mon–Fri 9:00–17:30) | X16: STD
A17: E0010 | B17: G&A | C17: San Francisco | D17: CA | E17: US | F17: M6 | G17: Exempt | H17: Salary | I17: 265000 | K17: USD | L17: US Semi-monthly | M17: 44088 | P17: E0000 | Q17: Active | R17: Employee | S17: 40 | T17: Full time | U17: =IF(AND(TRIM(E17)="US",TRIM(G17)="Non-Exempt"),"US Non-Exempt EEs","") | V17: =IF(AND(TRIM(E17)="US",TRIM(G17)="Non-Exempt"),IF(TRIM(D17)="CA","US California Non-Exempt","US Non-California Non-Exempt"),"") | W17: =_xlfn.XLOOKUP(X17,ShiftCodes[Code],ShiftCodes[Work Schedule],"Unknown code") -> Standard (Mon–Fri 9:00–17:30) | X17: STD
A18: E0011 | B18: On-Prem | C18: San Francisco | D18: CA | E18: US | F18: M5 | G18: Exempt | H18: Salary | I18: 308000 | K18: USD | L18: US Semi-monthly | M18: 44111 | P18: E0005 | Q18: Active | R18: Employee | S18: 40 | T18: Full time | U18: =IF(AND(TRIM(E18)="US",TRIM(G18)="Non-Exempt"),"US Non-Exempt EEs","") | V18: =IF(AND(TRIM(E18)="US",TRIM(G18)="Non-Exempt"),IF(TRIM(D18)="CA","US California Non-Exempt","US Non-California Non-Exempt"),"") | W18: =_xlfn.XLOOKUP(X18,ShiftCodes[Code],ShiftCodes[Work Schedule],"Unknown code") -> Standard (Mon–Fri 9:00–17:30) | X18: STD
A19: E0012 | B19: GPU Cloud | C19: San Francisco | D19: CA | E19: US | F19: M5 | G19: Exempt | H19: Salary | I19: 267000 | K19: USD | L19: US Semi-monthly | M19: 44149 | P19: E0002 | Q19: Active | R19: Employee | S19: 40 | T19: Full time | U19: =IF(AND(TRIM(E19)="US",TRIM(G19)="Non-Exempt"),"US Non-Exempt EEs","") | V19: =IF(AND(TRIM(E19)="US",TRIM(G19)="Non-Exempt"),IF(TRIM(D19)="CA","US California Non-Exempt","US Non-California Non-Exempt"),"") | W19: =_xlfn.XLOOKUP(X19,ShiftCodes[Code],ShiftCodes[Work Schedule],"Unknown code") -> Standard (Mon–Fri 9:00–17:30) | X19: STD
A20: E0013 | B20: On-Prem | C20: San Jose | D20: CA | E20: US | F20: M5 | G20: Exempt | H20: Salary | I20: 287000 | K20: USD | L20: US Semi-monthly | M20: 44210 | P20: E0005 | Q20: Active | R20: Employee | S20: 40 | T20: Full time | U20: =IF(AND(TRIM(E20)="US",TRIM(G20)="Non-Exempt"),"US Non-Exempt EEs","") | V20: =IF(AND(TRIM(E20)="US",TRIM(G20)="Non-Exempt"),IF(TRIM(D20)="CA","US California Non-Exempt","US Non-California Non-Exempt"),"") | W20: =_xlfn.XLOOKUP(X20,ShiftCodes[Code],ShiftCodes[Work Schedule],"Unknown code") -> Standard (Mon–Fri 9:00–17:30) | X20: STD
A21: E0014 | B21: On-Prem | C21: San Jose | D21: CA | E21: US | F21: M4 | G21: Exempt | H21: Salary | I21: 241000 | K21: USD | L21: US Semi-monthly | M21: 44277 | P21: E0011 | Q21: Active | R21: Employee | S21: 40 | T21: Full time | U21: =IF(AND(TRIM(E21)="US",TRIM(G21)="Non-Exempt"),"US Non-Exempt EEs","") | V21: =IF(AND(TRIM(E21)="US",TRIM(G21)="Non-Exempt"),IF(TRIM(D21)="CA","US California Non-Exempt","US Non-California Non-Exempt"),"") | W21: =_xlfn.XLOOKUP(X21,ShiftCodes[Code],ShiftCodes[Work Schedule],"Unknown code") -> Standard (Mon–Fri 9:00–17:30) | X21: STD
A22: E0015 | B22: On-Prem | C22: Austin | D22: TX | E22: US | F22: T2 | G22: Non-Exempt | H22: Hourly | J22: 35 | K22: USD | L22: US Biweekly | M22: 44305 | P22: E0014 | Q22: Active | R22: Employee | S22: 40 | T22: Full time | U22: =IF(AND(TRIM(E22)="US",TRIM(G22)="Non-Exempt"),"US Non-Exempt EEs","") -> US Non-Exempt EEs | V22: =IF(AND(TRIM(E22)="US",TRIM(G22)="Non-Exempt"),IF(TRIM(D22)="CA","US California Non-Exempt","US Non-California Non-Exempt"),"") -> US Non-California Non-Exempt | W22: =_xlfn.XLOOKUP(X22,ShiftCodes[Code],ShiftCodes[Work Schedule],"Unknown code") -> Shift B – Swing (Mon–Fri 14:00–22:30) | X22: SWNG
A23: E0016 | B23: GPU Cloud | C23: Seattle | D23: WA | E23: US | F23: M4 | G23: Exempt | H23: Salary | I23: 223000 | K23: USD | L23: US Semi-monthly | M23: 44378 | P23: E0003 | Q23: Active | R23: Employee | S23: 40 | T23: Full time | U23: =IF(AND(TRIM(E23)="US",TRIM(G23)="Non-Exempt"),"US Non-Exempt EEs","") | V23: =IF(AND(TRIM(E23)="US",TRIM(G23)="Non-Exempt"),IF(TRIM(D23)="CA","US California Non-Exempt","US Non-California Non-Exempt"),"") | W23: =_xlfn.XLOOKUP(X23,ShiftCodes[Code],ShiftCodes[Work Schedule],"Unknown code") -> Standard (Mon–Fri 9:00–17:30) | X23: STD
A24: E0017 | B24: GPU Cloud | C24: Remote-US | D24: WA | E24: US | F24: IC2 | G24: Exempt | H24: Salary | I24: 137000 | K24: USD | L24: US Semi-monthly | M24: 44440 | N24: 46318 | P24: E0016 | Q24: Termination pending | R24: Employee | S24: 40 | T24: Full time | U24: =IF(AND(TRIM(E24)="US",TRIM(G24)="Non-Exempt"),"US Non-Exempt EEs","") | V24: =IF(AND(TRIM(E24)="US",TRIM(G24)="Non-Exempt"),IF(TRIM(D24)="CA","US California Non-Exempt","US Non-California Non-Exempt"),"") | W24: =_xlfn.XLOOKUP(X24,ShiftCodes[Code],ShiftCodes[Work Schedule],"Unknown code") -> Standard (Mon–Fri 9:00–17:30) | X24: STD | Y24: Term date mid-period (US Semi-monthly Oct 16–31, 2026)
A25: E0018 | B25: G&A | C25: New York | D25: NY | E25: US | F25: M5 | G25: Exempt | H25: Salary | I25: 257000 | K25: USD | L25: US Semi-monthly | M25: 44455 | P25: E0010 | Q25: Active | R25: Employee | S25: 40 | T25: Full time | U25: =IF(AND(TRIM(E25)="US",TRIM(G25)="Non-Exempt"),"US Non-Exempt EEs","") | V25: =IF(AND(TRIM(E25)="US",TRIM(G25)="Non-Exempt"),IF(TRIM(D25)="CA","US California Non-Exempt","US Non-California Non-Exempt"),"") | W25: =_xlfn.XLOOKUP(X25,ShiftCodes[Code],ShiftCodes[Work Schedule],"Unknown code") -> Standard (Mon–Fri 9:00–17:30) | X25: STD
A26: E0019 | B26: On-Prem | C26: San Jose | D26: CA | E26: US | F26: M4 | G26: Exempt | H26: Salary | I26: 213000 | K26: USD | L26: US Semi-monthly | M26: 44461 | P26: E0011 | Q26: Active | R26: Employee | S26: 40 | T26: Full time | U26: =IF(AND(TRIM(E26)="US",TRIM(G26)="Non-Exempt"),"US Non-Exempt EEs","") | V26: =IF(AND(TRIM(E26)="US",TRIM(G26)="Non-Exempt"),IF(TRIM(D26)="CA","US California Non-Exempt","US Non-California Non-Exempt"),"") | W26: =_xlfn.XLOOKUP(X26,ShiftCodes[Code],ShiftCodes[Work Schedule],"Unknown code") -> Standard (Mon–Fri 9:00–17:30) | X26: STD
A27: E0020 | B27: On-Prem | C27: San Jose | D27: CA | E27: US | F27: T1 | G27: Non-Exempt | H27: Hourly | J27: 30 | K27: USD | L27: US Biweekly | M27: 44497 | P27: E0019 | Q27: Active | R27: Employee | S27: 40 | T27: Full time | U27: =IF(AND(TRIM(E27)="US",TRIM(G27)="Non-Exempt"),"US Non-Exempt EEs","") -> US Non-Exempt EEs | V27: =IF(AND(TRIM(E27)="US",TRIM(G27)="Non-Exempt"),IF(TRIM(D27)="CA","US California Non-Exempt","US Non-California Non-Exempt"),"") -> US California Non-Exempt | W27: =_xlfn.XLOOKUP(X27,ShiftCodes[Code],ShiftCodes[Work Schedule],"Unknown code") -> Shift A – Day (Mon–Fri 06:00–14:30) | X27: DAY
A28: E0023 | B28: On-Prem | C28: San Jose | D28: CA | E28: US | F28: T3 | G28: Non-Exempt | H28: Hourly | J28: 42.5 | K28: USD | L28: US Biweekly | M28: 44629 | P28: E0019 | Q28: Active | R28: Employee | S28: 40 | T28: Full time | U28: =IF(AND(TRIM(E28)="US",TRIM(G28)="Non-Exempt"),"US Non-Exempt EEs","") -> US Non-Exempt EEs | V28: =IF(AND(TRIM(E28)="US",TRIM(G28)="Non-Exempt"),IF(TRIM(D28)="CA","US California Non-Exempt","US Non-California Non-Exempt"),"") -> US California Non-Exempt | W28: =_xlfn.XLOOKUP(X28,ShiftCodes[Code],ShiftCodes[Work Schedule],"Unknown code") -> Shift B – Swing (Mon–Fri 14:00–22:30) | X28: SWNG
A29: E0024 | B29: Engineering | C29: San Francisco | D29: CA | E29: US | F29: M5 | G29: Exempt | H29: Salary | I29: 272000 | K29: USD | L29: US Semi-monthly | M29: 44646 | P29: E0007 | Q29: Active | R29: Employee | S29: 40 | T29: Full time | U29: =IF(AND(TRIM(E29)="US",TRIM(G29)="Non-Exempt"),"US Non-Exempt EEs","") | V29: =IF(AND(TRIM(E29)="US",TRIM(G29)="Non-Exempt"),IF(TRIM(D29)="CA","US California Non-Exempt","US Non-California Non-Exempt"),"") | W29: =_xlfn.XLOOKUP(X29,ShiftCodes[Code],ShiftCodes[Work Schedule],"Unknown code") -> Standard (Mon–Fri 9:00–17:30) | X29: STD
A30: E0025 | B30: On-Prem | C30: San Jose | D30: CA | E30: US | F30: T2 | G30: Non-Exempt | H30: Hourly | J30: 34.5 | K30: USD | L30: US Biweekly | M30: 44657 | P30: E0019 | Q30: Active | R30: Employee | S30: 40 | T30: Full time | U30: =IF(AND(TRIM(E30)="US",TRIM(G30)="Non-Exempt"),"US Non-Exempt EEs","") -> US Non-Exempt EEs | V30: =IF(AND(TRIM(E30)="US",TRIM(G30)="Non-Exempt"),IF(TRIM(D30)="CA","US California Non-Exempt","US Non-California Non-Exempt"),"") -> US California Non-Exempt | W30: =_xlfn.XLOOKUP(X30,ShiftCodes[Code],ShiftCodes[Work Schedule],"Unknown code") -> Shift B – Swing (Mon–Fri 14:00–22:30) | X30: SWNG
A31: E0026 | B31: G&A | C31: San Francisco | D31: CA | E31: US | F31: M5 | G31: Exempt | H31: Salary | I31: 246000 | K31: USD | L31: US Semi-monthly | M31: 44661 | P31: E0010 | Q31: Active | R31: Employee | S31: 40 | T31: Full time | U31: =IF(AND(TRIM(E31)="US",TRIM(G31)="Non-Exempt"),"US Non-Exempt EEs","") | V31: =IF(AND(TRIM(E31)="US",TRIM(G31)="Non-Exempt"),IF(TRIM(D31)="CA","US California Non-Exempt","US Non-California Non-Exempt"),"") | W31: =_xlfn.XLOOKUP(X31,ShiftCodes[Code],ShiftCodes[Work Schedule],"Unknown code") -> Standard (Mon–Fri 9:00–17:30) | X31: STD
A32: E0027 | B32: GPU Cloud | C32: San Francisco | D32: CA | E32: US | F32: M4 | G32: Exempt | H32: Salary | I32: 209000 | K32: USD | L32: US Semi-monthly | M32: 44684 | P32: E0012 | Q32: Active | R32: Employee | S32: 40 | T32: Full time | U32: =IF(AND(TRIM(E32)="US",TRIM(G32)="Non-Exempt"),"US Non-Exempt EEs","") | V32: =IF(AND(TRIM(E32)="US",TRIM(G32)="Non-Exempt"),IF(TRIM(D32)="CA","US California Non-Exempt","US Non-California Non-Exempt"),"") | W32: =_xlfn.XLOOKUP(X32,ShiftCodes[Code],ShiftCodes[Work Schedule],"Unknown code") -> Standard (Mon–Fri 9:00–17:30) | X32: STD
A33: E0028 | B33: On-Prem | C33: San Jose | D33: CA | E33: US | F33: T1 | G33: Non-Exempt | H33: Hourly | J33: 31.75 | K33: USD | L33: US Biweekly | M33: 44684 | N33: 46308 | P33: E0019 | Q33: Termination pending | R33: Employee | S33: 40 | T33: Full time | U33: =IF(AND(TRIM(E33)="US",TRIM(G33)="Non-Exempt"),"US Non-Exempt EEs","") -> US Non-Exempt EEs | V33: =IF(AND(TRIM(E33)="US",TRIM(G33)="Non-Exempt"),IF(TRIM(D33)="CA","US California Non-Exempt","US Non-California Non-Exempt"),"") -> US California Non-Exempt | W33: =_xlfn.XLOOKUP(X33,ShiftCodes[Code],ShiftCodes[Work Schedule],"Unknown code") -> Shift A – Day (Mon–Fri 06:00–14:30) | X33: DAY | Y33: Term date mid-period (US Biweekly Oct 4–17, 2026); timecards after Oct 13 removed (incl. Oct 14 off-schedule punch)
A34: E0029 | B34: On-Prem | C34: San Jose | D34: CA | E34: US | F34: T1 | G34: Non-Exempt | H34: Hourly | J34: 28 | K34: USD | L34: US Biweekly | M34: 44725 | N34: 46312 | P34: E0019 | Q34: Termination pending | R34: Employee | S34: 24 | T34: Part time | U34: =IF(AND(TRIM(E34)="US",TRIM(G34)="Non-Exempt"),"US Non-Exempt EEs","") -> US Non-Exempt EEs | V34: =IF(AND(TRIM(E34)="US",TRIM(G34)="Non-Exempt"),IF(TRIM(D34)="CA","US California Non-Exempt","US Non-California Non-Exempt"),"") -> US California Non-Exempt | W34: =_xlfn.XLOOKUP(X34,ShiftCodes[Code],ShiftCodes[Work Schedule],"Unknown code") -> Part-time – Day (Mon/Wed/Fri 06:00–14:30) | X34: PT | Y34: Term date = end of current pay period (US Biweekly Oct 4–17, 2026)
A35: E0030 | B35: Engineering | C35: San Francisco | D35: CA | E35: US | F35: M4 | G35: Exempt | H35: Salary | I35: 230000 | K35: USD | L35: US Semi-monthly | M35: 44734 | P35: E0024 | Q35: Active | R35: Employee | S35: 40 | T35: Full time | U35: =IF(AND(TRIM(E35)="US",TRIM(G35)="Non-Exempt"),"US Non-Exempt EEs","") | V35: =IF(AND(TRIM(E35)="US",TRIM(G35)="Non-Exempt"),IF(TRIM(D35)="CA","US California Non-Exempt","US Non-California Non-Exempt"),"") | W35: =_xlfn.XLOOKUP(X35,ShiftCodes[Code],ShiftCodes[Work Schedule],"Unknown code") -> Standard (Mon–Fri 9:00–17:30) | X35: STD
A36: E0031 | B36: Engineering | C36: San Francisco | D36: CA | E36: US | F36: IC2 | G36: Exempt | H36: Salary | I36: 143000 | K36: USD | L36: US Semi-monthly | M36: 44748 | O36: 46316 | P36: E0030 | Q36: On Leave(unpaid) | R36: Employee | S36: 40 | T36: Full time | U36: =IF(AND(TRIM(E36)="US",TRIM(G36)="Non-Exempt"),"US Non-Exempt EEs","") | V36: =IF(AND(TRIM(E36)="US",TRIM(G36)="Non-Exempt"),IF(TRIM(D36)="CA","US California Non-Exempt","US Non-California Non-Exempt"),"") | W36: =_xlfn.XLOOKUP(X36,ShiftCodes[Code],ShiftCodes[Work Schedule],"Unknown code") -> Standard (Mon–Fri 9:00–17:30) | X36: STD
A37: E0032 | B37: GPU Cloud | C37: Seattle | D37: WA | E37: US | F37: M4 | G37: Exempt | H37: Salary | I37: 223000 | K37: USD | L37: US Semi-monthly | M37: 44806 | P37: E0012 | Q37: Active | R37: Employee | S37: 40 | T37: Full time | U37: =IF(AND(TRIM(E37)="US",TRIM(G37)="Non-Exempt"),"US Non-Exempt EEs","") | V37: =IF(AND(TRIM(E37)="US",TRIM(G37)="Non-Exempt"),IF(TRIM(D37)="CA","US California Non-Exempt","US Non-California Non-Exempt"),"") | W37: =_xlfn.XLOOKUP(X37,ShiftCodes[Code],ShiftCodes[Work Schedule],"Unknown code") -> Standard (Mon–Fri 9:00–17:30) | X37: STD
A38: E0033 | B38: Engineering | C38: Seattle | D38: WA | E38: US | F38: M5 | G38: Exempt | H38: Salary | I38: 255000 | K38: USD | L38: US Semi-monthly | M38: 44816 | P38: E0007 | Q38: Active | R38: Employee | S38: 40 | T38: Full time | U38: =IF(AND(TRIM(E38)="US",TRIM(G38)="Non-Exempt"),"US Non-Exempt EEs","") | V38: =IF(AND(TRIM(E38)="US",TRIM(G38)="Non-Exempt"),IF(TRIM(D38)="CA","US California Non-Exempt","US Non-California Non-Exempt"),"") | W38: =_xlfn.XLOOKUP(X38,ShiftCodes[Code],ShiftCodes[Work Schedule],"Unknown code") -> Standard (Mon–Fri 9:00–17:30) | X38: STD
A39: E0034 | B39: On-Prem | C39: San Jose | D39: CA | E39: US | F39: T2 | G39: Non-Exempt | H39: Hourly | J39: 38.75 | K39: USD | L39: US Biweekly | M39: 44851 | P39: E0019 | Q39: Active | R39: Employee | S39: 40 | T39: Full time | U39: =IF(AND(TRIM(E39)="US",TRIM(G39)="Non-Exempt"),"US Non-Exempt EEs","") -> US Non-Exempt EEs | V39: =IF(AND(TRIM(E39)="US",TRIM(G39)="Non-Exempt"),IF(TRIM(D39)="CA","US California Non-Exempt","US Non-California Non-Exempt"),"") -> US California Non-Exempt | W39: =_xlfn.XLOOKUP(X39,ShiftCodes[Code],ShiftCodes[Work Schedule],"Unknown code") -> Shift A – Day (Mon–Fri 06:00–14:30) | X39: DAY
A40: E0035 | B40: Engineering | C40: San Francisco | D40: CA | E40: US | F40: IC1 | G40: Exempt | H40: Salary | I40: 101000 | K40: USD | L40: US Semi-monthly | M40: 44863 | P40: E0030 | Q40: Active | R40: Employee | S40: 40 | T40: Full time | U40: =IF(AND(TRIM(E40)="US",TRIM(G40)="Non-Exempt"),"US Non-Exempt EEs","") | V40: =IF(AND(TRIM(E40)="US",TRIM(G40)="Non-Exempt"),IF(TRIM(D40)="CA","US California Non-Exempt","US Non-California Non-Exempt"),"") | W40: =_xlfn.XLOOKUP(X40,ShiftCodes[Code],ShiftCodes[Work Schedule],"Unknown code") -> Standard (Mon–Fri 9:00–17:30) | X40: STD
...

Sheet absence balance
A1: Employee ID | B1: Plan | C1: Balance (hours or days) | D1: Last Accrual Date | E1: Notes | F1: Unit | H1: Balance As-Of Dates
A2: E0001 | B2: US Flexible PTO | C2: n/a (unlimited) | D2: {=IF(F2="n/a","—",IF(_xlfn.XLOOKUP(TRIM(SUBSTITUTE(A2,_xlfn.UNICHAR(160)," ")),TRIM(SUBSTITUTE('worker file'!$A$2:$A$406,_xlfn.UNICHAR(160)," ")),'worker file'!$L$2:$L$406,"")="US Biweekly",$I$3,$I$2))} -> — | F2: n/a | H2: Monthly & semi-monthly pay groups | I2: 46295
A3: E0021 | B3: US Hourly Vacation | C3: 46.5 | D3: {=IF(F3="n/a","—",IF(_xlfn.XLOOKUP(TRIM(SUBSTITUTE(A3,_xlfn.UNICHAR(160)," ")),TRIM(SUBSTITUTE('worker file'!$A$2:$A$406,_xlfn.UNICHAR(160)," ")),'worker file'!$L$2:$L$406,"")="US Biweekly",$I$3,$I$2))} -> 46298 | E3: Accrues per hour worked | F3: hrs | H3: US Biweekly (hourly US) | I3: 46298
A4: E0021 | B4: CA Paid Sick Leave | C4: 28 | D4: {=IF(F4="n/a","—",IF(_xlfn.XLOOKUP(TRIM(SUBSTITUTE(A4,_xlfn.UNICHAR(160)," ")),TRIM(SUBSTITUTE('worker file'!$A$2:$A$406,_xlfn.UNICHAR(160)," ")),'worker file'!$L$2:$L$406,"")="US Biweekly",$I$3,$I$2))} -> 46298 | F4: hrs
A5: E0006 | B5: UK Annual Leave | C5: 14.5 | D5: {=IF(F5="n/a","—",IF(_xlfn.XLOOKUP(TRIM(SUBSTITUTE(A5,_xlfn.UNICHAR(160)," ")),TRIM(SUBSTITUTE('worker file'!$A$2:$A$406,_xlfn.UNICHAR(160)," ")),'worker file'!$L$2:$L$406,"")="US Biweekly",$I$3,$I$2))} -> 46295 | E5: Holiday year Jan–Dec; Payout on termination | F5: days
A6: E0008 | B6: Canada Vacation | C6: 9 | D6: {=IF(F6="n/a","—",IF(_xlfn.XLOOKUP(TRIM(SUBSTITUTE(A6,_xlfn.UNICHAR(160)," ")),TRIM(SUBSTITUTE('worker file'!$A$2:$A$406,_xlfn.UNICHAR(160)," ")),'worker file'!$L$2:$L$406,"")="US Biweekly",$I$3,$I$2))} -> 46295 | E6: Ontario, 3 weeks/year | F6: days
A7: E0009 | B7: India Earned Leave | C7: 11 | D7: {=IF(F7="n/a","—",IF(_xlfn.XLOOKUP(TRIM(SUBSTITUTE(A7,_xlfn.UNICHAR(160)," ")),TRIM(SUBSTITUTE('worker file'!$A$2:$A$406,_xlfn.UNICHAR(160)," ")),'worker file'!$L$2:$L$406,"")="US Biweekly",$I$3,$I$2))} -> 46295 | E7: Karnataka S&E Act; Payout on termination | F7: days
A8: E0148 | B8: US Hourly Vacation | C8: 31 | D8: {=IF(F8="n/a","—",IF(_xlfn.XLOOKUP(TRIM(SUBSTITUTE(A8,_xlfn.UNICHAR(160)," ")),TRIM(SUBSTITUTE('worker file'!$A$2:$A$406,_xlfn.UNICHAR(160)," ")),'worker file'!$L$2:$L$406,"")="US Biweekly",$I$3,$I$2))} -> 46298 | E8: Payout on termination | F8: hrs
A9: E0148 | B9: CA Paid Sick Leave | D9: {=IF(F9="n/a","—",IF(_xlfn.XLOOKUP(TRIM(SUBSTITUTE(A9,_xlfn.UNICHAR(160)," ")),TRIM(SUBSTITUTE('worker file'!$A$2:$A$406,_xlfn.UNICHAR(160)," ")),'worker file'!$L$2:$L$406,"")="US Biweekly",$I$3,$I$2))} -> 46298 | E9: CA Labor Code 246; accrual cap 80 hrs; no payout on termination – balance needed | F9: hrs
A10: E0000 | B10: US Flexible PTO | C10: n/a (unlimited) | D10: {=IF(F10="n/a","—",IF(_xlfn.XLOOKUP(TRIM(SUBSTITUTE(A10,_xlfn.UNICHAR(160)," ")),TRIM(SUBSTITUTE('worker file'!$A$2:$A$406,_xlfn.UNICHAR(160)," ")),'worker file'!$L$2:$L$406,"")="US Biweekly",$I$3,$I$2))} -> — | E10: No accrual | F10: n/a
A11: E0000 | B11: CA Paid Sick Leave | C11: 67.75 | D11: {=IF(F11="n/a","—",IF(_xlfn.XLOOKUP(TRIM(SUBSTITUTE(A11,_xlfn.UNICHAR(160)," ")),TRIM(SUBSTITUTE('worker file'!$A$2:$A$406,_xlfn.UNICHAR(160)," ")),'worker file'!$L$2:$L$406,"")="US Biweekly",$I$3,$I$2))} -> 46295 | E11: CA Labor Code 246; accrual cap 80 hrs | F11: hrs
A12: E0002 | B12: US Flexible PTO | C12: n/a (unlimited) | D12: {=IF(F12="n/a","—",IF(_xlfn.XLOOKUP(TRIM(SUBSTITUTE(A12,_xlfn.UNICHAR(160)," ")),TRIM(SUBSTITUTE('worker file'!$A$2:$A$406,_xlfn.UNICHAR(160)," ")),'worker file'!$L$2:$L$406,"")="US Biweekly",$I$3,$I$2))} -> — | E12: No accrual | F12: n/a
A13: E0002 | B13: CA Paid Sick Leave | C13: 24.25 | D13: {=IF(F13="n/a","—",IF(_xlfn.XLOOKUP(TRIM(SUBSTITUTE(A13,_xlfn.UNICHAR(160)," ")),TRIM(SUBSTITUTE('worker file'!$A$2:$A$406,_xlfn.UNICHAR(160)," ")),'worker file'!$L$2:$L$406,"")="US Biweekly",$I$3,$I$2))} -> 46295 | E13: CA Labor Code 246; accrual cap 80 hrs | F13: hrs
A14: E0003 | B14: US Flexible PTO | C14: n/a (unlimited) | D14: {=IF(F14="n/a","—",IF(_xlfn.XLOOKUP(TRIM(SUBSTITUTE(A14,_xlfn.UNICHAR(160)," ")),TRIM(SUBSTITUTE('worker file'!$A$2:$A$406,_xlfn.UNICHAR(160)," ")),'worker file'!$L$2:$L$406,"")="US Biweekly",$I$3,$I$2))} -> — | E14: No accrual | F14: n/a
A15: E0004 | B15: US Flexible PTO | C15: n/a (unlimited) | D15: {=IF(F15="n/a","—",IF(_xlfn.XLOOKUP(TRIM(SUBSTITUTE(A15,_xlfn.UNICHAR(160)," ")),TRIM(SUBSTITUTE('worker file'!$A$2:$A$406,_xlfn.UNICHAR(160)," ")),'worker file'!$L$2:$L$406,"")="US Biweekly",$I$3,$I$2))} -> — | E15: No accrual | F15: n/a
A16: E0005 | B16: US Flexible PTO | C16: n/a (unlimited) | D16: {=IF(F16="n/a","—",IF(_xlfn.XLOOKUP(TRIM(SUBSTITUTE(A16,_xlfn.UNICHAR(160)," ")),TRIM(SUBSTITUTE('worker file'!$A$2:$A$406,_xlfn.UNICHAR(160)," ")),'worker file'!$L$2:$L$406,"")="US Biweekly",$I$3,$I$2))} -> — | E16: No accrual | F16: n/a
A17: E0005 | B17: CA Paid Sick Leave | C17: 63.5 | D17: {=IF(F17="n/a","—",IF(_xlfn.XLOOKUP(TRIM(SUBSTITUTE(A17,_xlfn.UNICHAR(160)," ")),TRIM(SUBSTITUTE('worker file'!$A$2:$A$406,_xlfn.UNICHAR(160)," ")),'worker file'!$L$2:$L$406,"")="US Biweekly",$I$3,$I$2))} -> 46295 | E17: CA Labor Code 246; accrual cap 80 hrs | F17: hrs
A18: E0007 | B18: US Flexible PTO | C18: n/a (unlimited) | D18: {=IF(F18="n/a","—",IF(_xlfn.XLOOKUP(TRIM(SUBSTITUTE(A18,_xlfn.UNICHAR(160)," ")),TRIM(SUBSTITUTE('worker file'!$A$2:$A$406,_xlfn.UNICHAR(160)," ")),'worker file'!$L$2:$L$406,"")="US Biweekly",$I$3,$I$2))} -> — | E18: No accrual | F18: n/a
A19: E0007 | B19: CA Paid Sick Leave | C19: 68 | D19: {=IF(F19="n/a","—",IF(_xlfn.XLOOKUP(TRIM(SUBSTITUTE(A19,_xlfn.UNICHAR(160)," ")),TRIM(SUBSTITUTE('worker file'!$A$2:$A$406,_xlfn.UNICHAR(160)," ")),'worker file'!$L$2:$L$406,"")="US Biweekly",$I$3,$I$2))} -> 46295 | E19: CA Labor Code 246; accrual cap 80 hrs | F19: hrs
A20: E0010 | B20: US Flexible PTO | C20: n/a (unlimited) | D20: {=IF(F20="n/a","—",IF(_xlfn.XLOOKUP(TRIM(SUBSTITUTE(A20,_xlfn.UNICHAR(160)," ")),TRIM(SUBSTITUTE('worker file'!$A$2:$A$406,_xlfn.UNICHAR(160)," ")),'worker file'!$L$2:$L$406,"")="US Biweekly",$I$3,$I$2))} -> — | E20: No accrual | F20: n/a
A21: E0010 | B21: CA Paid Sick Leave | C21: 61.75 | D21: {=IF(F21="n/a","—",IF(_xlfn.XLOOKUP(TRIM(SUBSTITUTE(A21,_xlfn.UNICHAR(160)," ")),TRIM(SUBSTITUTE('worker file'!$A$2:$A$406,_xlfn.UNICHAR(160)," ")),'worker file'!$L$2:$L$406,"")="US Biweekly",$I$3,$I$2))} -> 46295 | E21: CA Labor Code 246; accrual cap 80 hrs | F21: hrs
A22: E0011 | B22: US Flexible PTO | C22: n/a (unlimited) | D22: {=IF(F22="n/a","—",IF(_xlfn.XLOOKUP(TRIM(SUBSTITUTE(A22,_xlfn.UNICHAR(160)," ")),TRIM(SUBSTITUTE('worker file'!$A$2:$A$406,_xlfn.UNICHAR(160)," ")),'worker file'!$L$2:$L$406,"")="US Biweekly",$I$3,$I$2))} -> — | E22: No accrual | F22: n/a
A23: E0011 | B23: CA Paid Sick Leave | C23: 63 | D23: {=IF(F23="n/a","—",IF(_xlfn.XLOOKUP(TRIM(SUBSTITUTE(A23,_xlfn.UNICHAR(160)," ")),TRIM(SUBSTITUTE('worker file'!$A$2:$A$406,_xlfn.UNICHAR(160)," ")),'worker file'!$L$2:$L$406,"")="US Biweekly",$I$3,$I$2))} -> 46295 | E23: CA Labor Code 246; accrual cap 80 hrs | F23: hrs
A24: E0012 | B24: US Flexible PTO | C24: n/a (unlimited) | D24: {=IF(F24="n/a","—",IF(_xlfn.XLOOKUP(TRIM(SUBSTITUTE(A24,_xlfn.UNICHAR(160)," ")),TRIM(SUBSTITUTE('worker file'!$A$2:$A$406,_xlfn.UNICHAR(160)," ")),'worker file'!$L$2:$L$406,"")="US Biweekly",$I$3,$I$2))} -> — | E24: No accrual | F24: n/a
A25: E0012 | B25: CA Paid Sick Leave | C25: 54.25 | D25: {=IF(F25="n/a","—",IF(_xlfn.XLOOKUP(TRIM(SUBSTITUTE(A25,_xlfn.UNICHAR(160)," ")),TRIM(SUBSTITUTE('worker file'!$A$2:$A$406,_xlfn.UNICHAR(160)," ")),'worker file'!$L$2:$L$406,"")="US Biweekly",$I$3,$I$2))} -> 46295 | E25: CA Labor Code 246; accrual cap 80 hrs | F25: hrs
A26: E0013 | B26: US Flexible PTO | C26: n/a (unlimited) | D26: {=IF(F26="n/a","—",IF(_xlfn.XLOOKUP(TRIM(SUBSTITUTE(A26,_xlfn.UNICHAR(160)," ")),TRIM(SUBSTITUTE('worker file'!$A$2:$A$406,_xlfn.UNICHAR(160)," ")),'worker file'!$L$2:$L$406,"")="US Biweekly",$I$3,$I$2))} -> — | E26: No accrual | F26: n/a
A27: E0013 | B27: CA Paid Sick Leave | C27: 73.5 | D27: {=IF(F27="n/a","—",IF(_xlfn.XLOOKUP(TRIM(SUBSTITUTE(A27,_xlfn.UNICHAR(160)," ")),TRIM(SUBSTITUTE('worker file'!$A$2:$A$406,_xlfn.UNICHAR(160)," ")),'worker file'!$L$2:$L$406,"")="US Biweekly",$I$3,$I$2))} -> 46295 | E27: CA Labor Code 246; accrual cap 80 hrs | F27: hrs
A28: E0014 | B28: US Flexible PTO | C28: n/a (unlimited) | D28: {=IF(F28="n/a","—",IF(_xlfn.XLOOKUP(TRIM(SUBSTITUTE(A28,_xlfn.UNICHAR(160)," ")),TRIM(SUBSTITUTE('worker file'!$A$2:$A$406,_xlfn.UNICHAR(160)," ")),'worker file'!$L$2:$L$406,"")="US Biweekly",$I$3,$I$2))} -> — | E28: No accrual | F28: n/a
A29: E0015 | B29: US Hourly Vacation | C29: 120 | D29: {=IF(F29="n/a","—",IF(_xlfn.XLOOKUP(TRIM(SUBSTITUTE(A29,_xlfn.UNICHAR(160)," ")),TRIM(SUBSTITUTE('worker file'!$A$2:$A$406,_xlfn.UNICHAR(160)," ")),'worker file'!$L$2:$L$406,"")="US Biweekly",$I$3,$I$2))} -> 46298 | E29: Accrues per hour worked; cap 120 hrs | F29: hrs
A30: E0015 | B30: TX Hourly Sick (company) | C30: 6.5 | D30: {=IF(F30="n/a","—",IF(_xlfn.XLOOKUP(TRIM(SUBSTITUTE(A30,_xlfn.UNICHAR(160)," ")),TRIM(SUBSTITUTE('worker file'!$A$2:$A$406,_xlfn.UNICHAR(160)," ")),'worker file'!$L$2:$L$406,"")="US Biweekly",$I$3,$I$2))} -> 46298 | E30: Company policy; 40 hrs/yr | F30: hrs
A31: E0016 | B31: US Flexible PTO | C31: n/a (unlimited) | D31: {=IF(F31="n/a","—",IF(_xlfn.XLOOKUP(TRIM(SUBSTITUTE(A31,_xlfn.UNICHAR(160)," ")),TRIM(SUBSTITUTE('worker file'!$A$2:$A$406,_xlfn.UNICHAR(160)," ")),'worker file'!$L$2:$L$406,"")="US Biweekly",$I$3,$I$2))} -> — | E31: No accrual | F31: n/a
A32: E0017 | B32: US Flexible PTO | C32: n/a (unlimited) | D32: {=IF(F32="n/a","—",IF(_xlfn.XLOOKUP(TRIM(SUBSTITUTE(A32,_xlfn.UNICHAR(160)," ")),TRIM(SUBSTITUTE('worker file'!$A$2:$A$406,_xlfn.UNICHAR(160)," ")),'worker file'!$L$2:$L$406,"")="US Biweekly",$I$3,$I$2))} -> — | E32: No accrual | F32: n/a
A33: E0018 | B33: US Flexible PTO | C33: n/a (unlimited) | D33: {=IF(F33="n/a","—",IF(_xlfn.XLOOKUP(TRIM(SUBSTITUTE(A33,_xlfn.UNICHAR(160)," ")),TRIM(SUBSTITUTE('worker file'!$A$2:$A$406,_xlfn.UNICHAR(160)," ")),'worker file'!$L$2:$L$406,"")="US Biweekly",$I$3,$I$2))} -> — | E33: No accrual | F33: n/a
A34: E0018 | B34: NY Paid Sick Leave | C34: 47.25 | D34: {=IF(F34="n/a","—",IF(_xlfn.XLOOKUP(TRIM(SUBSTITUTE(A34,_xlfn.UNICHAR(160)," ")),TRIM(SUBSTITUTE('worker file'!$A$2:$A$406,_xlfn.UNICHAR(160)," ")),'worker file'!$L$2:$L$406,"")="US Biweekly",$I$3,$I$2))} -> 46295 | E34: NY Labor Law 196-b; 56 hrs/yr | F34: hrs
A35: E0019 | B35: US Flexible PTO | C35: n/a (unlimited) | D35: {=IF(F35="n/a","—",IF(_xlfn.XLOOKUP(TRIM(SUBSTITUTE(A35,_xlfn.UNICHAR(160)," ")),TRIM(SUBSTITUTE('worker file'!$A$2:$A$406,_xlfn.UNICHAR(160)," ")),'worker file'!$L$2:$L$406,"")="US Biweekly",$I$3,$I$2))} -> — | E35: No accrual | F35: n/a
A36: E0019 | B36: CA Paid Sick Leave | C36: 47.5 | D36: {=IF(F36="n/a","—",IF(_xlfn.XLOOKUP(TRIM(SUBSTITUTE(A36,_xlfn.UNICHAR(160)," ")),TRIM(SUBSTITUTE('worker file'!$A$2:$A$406,_xlfn.UNICHAR(160)," ")),'worker file'!$L$2:$L$406,"")="US Biweekly",$I$3,$I$2))} -> 46295 | E36: CA Labor Code 246; accrual cap 80 hrs | F36: hrs
A37: E0020 | B37: US Hourly Vacation | C37: 120 | D37: {=IF(F37="n/a","—",IF(_xlfn.XLOOKUP(TRIM(SUBSTITUTE(A37,_xlfn.UNICHAR(160)," ")),TRIM(SUBSTITUTE('worker file'!$A$2:$A$406,_xlfn.UNICHAR(160)," ")),'worker file'!$L$2:$L$406,"")="US Biweekly",$I$3,$I$2))} -> 46298 | E37: Accrues per hour worked; cap 120 hrs | F37: hrs
A38: E0020 | B38: CA Paid Sick Leave | C38: 31.75 | D38: {=IF(F38="n/a","—",IF(_xlfn.XLOOKUP(TRIM(SUBSTITUTE(A38,_xlfn.UNICHAR(160)," ")),TRIM(SUBSTITUTE('worker file'!$A$2:$A$406,_xlfn.UNICHAR(160)," ")),'worker file'!$L$2:$L$406,"")="US Biweekly",$I$3,$I$2))} -> 46298 | E38: CA Labor Code 246; accrual cap 80 hrs | F38: hrs
A39: E0022 | B39: US Hourly Vacation | C39: 77.25 | D39: {=IF(F39="n/a","—",IF(_xlfn.XLOOKUP(TRIM(SUBSTITUTE(A39,_xlfn.UNICHAR(160)," ")),TRIM(SUBSTITUTE('worker file'!$A$2:$A$406,_xlfn.UNICHAR(160)," ")),'worker file'!$L$2:$L$406,"")="US Biweekly",$I$3,$I$2))} -> 46298 | E39: Accrues per hour worked; cap 120 hrs | F39: hrs
A40: E0022 | B40: TX Hourly Sick (company) | C40: 28 | D40: {=IF(F40="n/a","—",IF(_xlfn.XLOOKUP(TRIM(SUBSTITUTE(A40,_xlfn.UNICHAR(160)," ")),TRIM(SUBSTITUTE('worker file'!$A$2:$A$406,_xlfn.UNICHAR(160)," ")),'worker file'!$L$2:$L$406,"")="US Biweekly",$I$3,$I$2))} -> 46298 | E40: Company policy; 40 hrs/yr | F40: hrs
...

Sheet Payroll inputs
A1: Payroll Inputs – Ongoing Employee Deductions (US)
A2: Deduction codes & default rates (blue = editable input). Benefits are flat $ per pay period (Medical $200, Dental $44, Vision $30); 401(k) % set per employee in the table below.
F3: Default Rate / Amount
A4: Code | B4: Description | C4: Deduction Type | D4: Tax Treatment | E4: Calc Method | F4: Default Rate | G4: Basis | H4: Frequency
A5: 401K_EE | B5: 401(k) Employee Deferral | C5: Retirement | D5: Pre-tax (exempt from FIT/SIT; subject to FICA) | E5: Percent | F5: Per employee | G5: Gross pay | H5: Every pay period (ongoing)
A6: MED_EE | B6: Medical (Health) – Employee | C6: Benefits | D6: Pre-tax Section 125 (exempt from FIT/SIT/FICA) | E6: Flat | F6: 200 | G6: Per pay period | H6: Every pay period (ongoing)
A7: DEN_EE | B7: Dental – Employee | C7: Benefits | D7: Pre-tax Section 125 (exempt from FIT/SIT/FICA) | E7: Flat | F7: 44 | G7: Per pay period | H7: Every pay period (ongoing)
A8: VIS_EE | B8: Vision – Employee | C8: Benefits | D8: Pre-tax Section 125 (exempt from FIT/SIT/FICA) | E8: Flat | F8: 30 | G8: Per pay period | H8: Every pay period (ongoing)
B9: Total benefits (Health + Dental + Vision) | F9: =SUM(F6:F8) -> 274
A11: Employee ID | B11: Pay Group | C11: State | D11: Worker Status | E11: Deduction Code | F11: Description | G11: Tax Treatment | H11: Calc Method | I11: Rate (%) | J11: Flat Amount | K11: Basis | L11: Frequency | M11: Effective Start | N11: Effective End | O11: Notes
A12: E0001 | B12: {=_xlfn.XLOOKUP($A12,TRIM(SUBSTITUTE('worker file'!$A$2:$A$406,_xlfn.UNICHAR(160)," ")),'worker file'!$L$2:$L$406,"Not found")} -> US Semi-monthly | C12: {=_xlfn.XLOOKUP($A12,TRIM(SUBSTITUTE('worker file'!$A$2:$A$406,_xlfn.UNICHAR(160)," ")),'worker file'!$D$2:$D$406,"Not found")} -> CA | D12: {=_xlfn.XLOOKUP($A12,TRIM(SUBSTITUTE('worker file'!$A$2:$A$406,_xlfn.UNICHAR(160)," ")),'worker file'!$Q$2:$Q$406,"Not found")} -> Active | E12: 401K_EE | F12: =_xlfn.XLOOKUP($E12,$A$5:$A$8,$B$5:$B$8,"") -> 401(k) Employee Deferral | G12: =_xlfn.XLOOKUP($E12,$A$5:$A$8,$D$5:$D$8,"") -> Pre-tax (exempt from FIT/SIT; subject to FICA) | H12: =_xlfn.XLOOKUP($E12,$A$5:$A$8,$E$5:$E$8,"") -> Percent | I12: 0.03 | J12: =IF($H12="Flat",_xlfn.XLOOKUP($E12,$A$5:$A$8,$F$5:$F$8,""),"") | K12: =_xlfn.XLOOKUP($E12,$A$5:$A$8,$G$5:$G$8,"") -> Gross pay | L12: =_xlfn.XLOOKUP($E12,$A$5:$A$8,$H$5:$H$8,"") -> Every pay period (ongoing) | M12: {=MAX(_xlfn.XLOOKUP($A12,TRIM(SUBSTITUTE('worker file'!$A$2:$A$406,_xlfn.UNICHAR(160)," ")),'worker file'!$M$2:$M$406,0),_xlfn.XLOOKUP($B12,TRIM('pay group & schedule'!$A$2:$A$6),'pay group & schedule'!$D$2:$D$6,0))} -> 46311 | N12: {=_xlfn.LET(_xlpm.t,_xlfn.XLOOKUP($A12,TRIM(SUBSTITUTE('worker file'!$A$2:$A$406,_xlfn.UNICHAR(160)," ")),'worker file'!$N$2:$N$406,""),IF(N(_xlpm.t)=0,"",_xlpm.t))}
A13: E0001 | B13: {=_xlfn.XLOOKUP($A13,TRIM(SUBSTITUTE('worker file'!$A$2:$A$406,_xlfn.UNICHAR(160)," ")),'worker file'!$L$2:$L$406,"Not found")} -> US Semi-monthly | C13: {=_xlfn.XLOOKUP($A13,TRIM(SUBSTITUTE('worker file'!$A$2:$A$406,_xlfn.UNICHAR(160)," ")),'worker file'!$D$2:$D$406,"Not found")} -> CA | D13: {=_xlfn.XLOOKUP($A13,TRIM(SUBSTITUTE('worker file'!$A$2:$A$406,_xlfn.UNICHAR(160)," ")),'worker file'!$Q$2:$Q$406,"Not found")} -> Active | E13: MED_EE | F13: =_xlfn.XLOOKUP($E13,$A$5:$A$8,$B$5:$B$8,"") -> Medical (Health) – Employee | G13: =_xlfn.XLOOKUP($E13,$A$5:$A$8,$D$5:$D$8,"") -> Pre-tax Section 125 (exempt from FIT/SIT/FICA) | H13: =_xlfn.XLOOKUP($E13,$A$5:$A$8,$E$5:$E$8,"") -> Flat | I13: =IF($H13="Percent",_xlfn.XLOOKUP($E13,$A$5:$A$8,$F$5:$F$8,""),"") | J13: =IF($H13="Flat",_xlfn.XLOOKUP($E13,$A$5:$A$8,$F$5:$F$8,""),"") -> 200 | K13: =_xlfn.XLOOKUP($E13,$A$5:$A$8,$G$5:$G$8,"") -> Per pay period | L13: =_xlfn.XLOOKUP($E13,$A$5:$A$8,$H$5:$H$8,"") -> Every pay period (ongoing) | M13: {=MAX(_xlfn.XLOOKUP($A13,TRIM(SUBSTITUTE('worker file'!$A$2:$A$406,_xlfn.UNICHAR(160)," ")),'worker file'!$M$2:$M$406,0),_xlfn.XLOOKUP($B13,TRIM('pay group & schedule'!$A$2:$A$6),'pay group & schedule'!$D$2:$D$6,0))} -> 46311 | N13: {=_xlfn.LET(_xlpm.t,_xlfn.XLOOKUP($A13,TRIM(SUBSTITUTE('worker file'!$A$2:$A$406,_xlfn.UNICHAR(160)," ")),'worker file'!$N$2:$N$406,""),IF(N(_xlpm.t)=0,"",_xlpm.t))}
A14: E0001 | B14: {=_xlfn.XLOOKUP($A14,TRIM(SUBSTITUTE('worker file'!$A$2:$A$406,_xlfn.UNICHAR(160)," ")),'worker file'!$L$2:$L$406,"Not found")} -> US Semi-monthly | C14: {=_xlfn.XLOOKUP($A14,TRIM(SUBSTITUTE('worker file'!$A$2:$A$406,_xlfn.UNICHAR(160)," ")),'worker file'!$D$2:$D$406,"Not found")} -> CA | D14: {=_xlfn.XLOOKUP($A14,TRIM(SUBSTITUTE('worker file'!$A$2:$A$406,_xlfn.UNICHAR(160)," ")),'worker file'!$Q$2:$Q$406,"Not found")} -> Active | E14: DEN_EE | F14: =_xlfn.XLOOKUP($E14,$A$5:$A$8,$B$5:$B$8,"") -> Dental – Employee | G14: =_xlfn.XLOOKUP($E14,$A$5:$A$8,$D$5:$D$8,"") -> Pre-tax Section 125 (exempt from FIT/SIT/FICA) | H14: =_xlfn.XLOOKUP($E14,$A$5:$A$8,$E$5:$E$8,"") -> Flat | I14: =IF($H14="Percent",_xlfn.XLOOKUP($E14,$A$5:$A$8,$F$5:$F$8,""),"") | J14: =IF($H14="Flat",_xlfn.XLOOKUP($E14,$A$5:$A$8,$F$5:$F$8,""),"") -> 44 | K14: =_xlfn.XLOOKUP($E14,$A$5:$A$8,$G$5:$G$8,"") -> Per pay period | L14: =_xlfn.XLOOKUP($E14,$A$5:$A$8,$H$5:$H$8,"") -> Every pay period (ongoing) | M14: {=MAX(_xlfn.XLOOKUP($A14,TRIM(SUBSTITUTE('worker file'!$A$2:$A$406,_xlfn.UNICHAR(160)," ")),'worker file'!$M$2:$M$406,0),_xlfn.XLOOKUP($B14,TRIM('pay group & schedule'!$A$2:$A$6),'pay group & schedule'!$D$2:$D$6,0))} -> 46311 | N14: {=_xlfn.LET(_xlpm.t,_xlfn.XLOOKUP($A14,TRIM(SUBSTITUTE('worker file'!$A$2:$A$406,_xlfn.UNICHAR(160)," ")),'worker file'!$N$2:$N$406,""),IF(N(_xlpm.t)=0,"",_xlpm.t))}
A15: E0001 | B15: {=_xlfn.XLOOKUP($A15,TRIM(SUBSTITUTE('worker file'!$A$2:$A$406,_xlfn.UNICHAR(160)," ")),'worker file'!$L$2:$L$406,"Not found")} -> US Semi-monthly | C15: {=_xlfn.XLOOKUP($A15,TRIM(SUBSTITUTE('worker file'!$A$2:$A$406,_xlfn.UNICHAR(160)," ")),'worker file'!$D$2:$D$406,"Not found")} -> CA | D15: {=_xlfn.XLOOKUP($A15,TRIM(SUBSTITUTE('worker file'!$A$2:$A$406,_xlfn.UNICHAR(160)," ")),'worker file'!$Q$2:$Q$406,"Not found")} -> Active | E15: VIS_EE | F15: =_xlfn.XLOOKUP($E15,$A$5:$A$8,$B$5:$B$8,"") -> Vision – Employee | G15: =_xlfn.XLOOKUP($E15,$A$5:$A$8,$D$5:$D$8,"") -> Pre-tax Section 125 (exempt from FIT/SIT/FICA) | H15: =_xlfn.XLOOKUP($E15,$A$5:$A$8,$E$5:$E$8,"") -> Flat | I15: =IF($H15="Percent",_xlfn.XLOOKUP($E15,$A$5:$A$8,$F$5:$F$8,""),"") | J15: =IF($H15="Flat",_xlfn.XLOOKUP($E15,$A$5:$A$8,$F$5:$F$8,""),"") -> 30 | K15: =_xlfn.XLOOKUP($E15,$A$5:$A$8,$G$5:$G$8,"") -> Per pay period | L15: =_xlfn.XLOOKUP($E15,$A$5:$A$8,$H$5:$H$8,"") -> Every pay period (ongoing) | M15: {=MAX(_xlfn.XLOOKUP($A15,TRIM(SUBSTITUTE('worker file'!$A$2:$A$406,_xlfn.UNICHAR(160)," ")),'worker file'!$M$2:$M$406,0),_xlfn.XLOOKUP($B15,TRIM('pay group & schedule'!$A$2:$A$6),'pay group & schedule'!$D$2:$D$6,0))} -> 46311 | N15: {=_xlfn.LET(_xlpm.t,_xlfn.XLOOKUP($A15,TRIM(SUBSTITUTE('worker file'!$A$2:$A$406,_xlfn.UNICHAR(160)," ")),'worker file'!$N$2:$N$406,""),IF(N(_xlpm.t)=0,"",_xlpm.t))}
A16: E0004 | B16: {=_xlfn.XLOOKUP($A16,TRIM(SUBSTITUTE('worker file'!$A$2:$A$406,_xlfn.UNICHAR(160)," ")),'worker file'!$L$2:$L$406,"Not found")} -> US Semi-monthly | C16: {=_xlfn.XLOOKUP($A16,TRIM(SUBSTITUTE('worker file'!$A$2:$A$406,_xlfn.UNICHAR(160)," ")),'worker file'!$D$2:$D$406,"Not found")} -> WA | D16: {=_xlfn.XLOOKUP($A16,TRIM(SUBSTITUTE('worker file'!$A$2:$A$406,_xlfn.UNICHAR(160)," ")),'worker file'!$Q$2:$Q$406,"Not found")} -> Termination pending | E16: MED_EE | F16: =_xlfn.XLOOKUP($E16,$A$5:$A$8,$B$5:$B$8,"") -> Medical (Health) – Employee | G16: =_xlfn.XLOOKUP($E16,$A$5:$A$8,$D$5:$D$8,"") -> Pre-tax Section 125 (exempt from FIT/SIT/FICA) | H16: =_xlfn.XLOOKUP($E16,$A$5:$A$8,$E$5:$E$8,"") -> Flat | I16: =IF($H16="Percent",_xlfn.XLOOKUP($E16,$A$5:$A$8,$F$5:$F$8,""),"") | J16: =IF($H16="Flat",_xlfn.XLOOKUP($E16,$A$5:$A$8,$F$5:$F$8,""),"") -> 200 | K16: =_xlfn.XLOOKUP($E16,$A$5:$A$8,$G$5:$G$8,"") -> Per pay period | L16: =_xlfn.XLOOKUP($E16,$A$5:$A$8,$H$5:$H$8,"") -> Every pay period (ongoing) | M16: {=MAX(_xlfn.XLOOKUP($A16,TRIM(SUBSTITUTE('worker file'!$A$2:$A$406,_xlfn.UNICHAR(160)," ")),'worker file'!$M$2:$M$406,0),_xlfn.XLOOKUP($B16,TRIM('pay group & schedule'!$A$2:$A$6),'pay group & schedule'!$D$2:$D$6,0))} -> 46311 | N16: {=_xlfn.LET(_xlpm.t,_xlfn.XLOOKUP($A16,TRIM(SUBSTITUTE('worker file'!$A$2:$A$406,_xlfn.UNICHAR(160)," ")),'worker file'!$N$2:$N$406,""),IF(N(_xlpm.t)=0,"",_xlpm.t))} -> 46326 | O16: Ongoing until term date; stop after final pay
A17: E0004 | B17: {=_xlfn.XLOOKUP($A17,TRIM(SUBSTITUTE('worker file'!$A$2:$A$406,_xlfn.UNICHAR(160)," ")),'worker file'!$L$2:$L$406,"Not found")} -> US Semi-monthly | C17: {=_xlfn.XLOOKUP($A17,TRIM(SUBSTITUTE('worker file'!$A$2:$A$406,_xlfn.UNICHAR(160)," ")),'worker file'!$D$2:$D$406,"Not found")} -> WA | D17: {=_xlfn.XLOOKUP($A17,TRIM(SUBSTITUTE('worker file'!$A$2:$A$406,_xlfn.UNICHAR(160)," ")),'worker file'!$Q$2:$Q$406,"Not found")} -> Termination pending | E17: DEN_EE | F17: =_xlfn.XLOOKUP($E17,$A$5:$A$8,$B$5:$B$8,"") -> Dental – Employee | G17: =_xlfn.XLOOKUP($E17,$A$5:$A$8,$D$5:$D$8,"") -> Pre-tax Section 125 (exempt from FIT/SIT/FICA) | H17: =_xlfn.XLOOKUP($E17,$A$5:$A$8,$E$5:$E$8,"") -> Flat | I17: =IF($H17="Percent",_xlfn.XLOOKUP($E17,$A$5:$A$8,$F$5:$F$8,""),"") | J17: =IF($H17="Flat",_xlfn.XLOOKUP($E17,$A$5:$A$8,$F$5:$F$8,""),"") -> 44 | K17: =_xlfn.XLOOKUP($E17,$A$5:$A$8,$G$5:$G$8,"") -> Per pay period | L17: =_xlfn.XLOOKUP($E17,$A$5:$A$8,$H$5:$H$8,"") -> Every pay period (ongoing) | M17: {=MAX(_xlfn.XLOOKUP($A17,TRIM(SUBSTITUTE('worker file'!$A$2:$A$406,_xlfn.UNICHAR(160)," ")),'worker file'!$M$2:$M$406,0),_xlfn.XLOOKUP($B17,TRIM('pay group & schedule'!$A$2:$A$6),'pay group & schedule'!$D$2:$D$6,0))} -> 46311 | N17: {=_xlfn.LET(_xlpm.t,_xlfn.XLOOKUP($A17,TRIM(SUBSTITUTE('worker file'!$A$2:$A$406,_xlfn.UNICHAR(160)," ")),'worker file'!$N$2:$N$406,""),IF(N(_xlpm.t)=0,"",_xlpm.t))} -> 46326 | O17: Ongoing until term date; stop after final pay
A18: E0004 | B18: {=_xlfn.XLOOKUP($A18,TRIM(SUBSTITUTE('worker file'!$A$2:$A$406,_xlfn.UNICHAR(160)," ")),'worker file'!$L$2:$L$406,"Not found")} -> US Semi-monthly | C18: {=_xlfn.XLOOKUP($A18,TRIM(SUBSTITUTE('worker file'!$A$2:$A$406,_xlfn.UNICHAR(160)," ")),'worker file'!$D$2:$D$406,"Not found")} -> WA | D18: {=_xlfn.XLOOKUP($A18,TRIM(SUBSTITUTE('worker file'!$A$2:$A$406,_xlfn.UNICHAR(160)," ")),'worker file'!$Q$2:$Q$406,"Not found")} -> Termination pending | E18: VIS_EE | F18: =_xlfn.XLOOKUP($E18,$A$5:$A$8,$B$5:$B$8,"") -> Vision – Employee | G18: =_xlfn.XLOOKUP($E18,$A$5:$A$8,$D$5:$D$8,"") -> Pre-tax Section 125 (exempt from FIT/SIT/FICA) | H18: =_xlfn.XLOOKUP($E18,$A$5:$A$8,$E$5:$E$8,"") -> Flat | I18: =IF($H18="Percent",_xlfn.XLOOKUP($E18,$A$5:$A$8,$F$5:$F$8,""),"") | J18: =IF($H18="Flat",_xlfn.XLOOKUP($E18,$A$5:$A$8,$F$5:$F$8,""),"") -> 30 | K18: =_xlfn.XLOOKUP($E18,$A$5:$A$8,$G$5:$G$8,"") -> Per pay period | L18: =_xlfn.XLOOKUP($E18,$A$5:$A$8,$H$5:$H$8,"") -> Every pay period (ongoing) | M18: {=MAX(_xlfn.XLOOKUP($A18,TRIM(SUBSTITUTE('worker file'!$A$2:$A$406,_xlfn.UNICHAR(160)," ")),'worker file'!$M$2:$M$406,0),_xlfn.XLOOKUP($B18,TRIM('pay group & schedule'!$A$2:$A$6),'pay group & schedule'!$D$2:$D$6,0))} -> 46311 | N18: {=_xlfn.LET(_xlpm.t,_xlfn.XLOOKUP($A18,TRIM(SUBSTITUTE('worker file'!$A$2:$A$406,_xlfn.UNICHAR(160)," ")),'worker file'!$N$2:$N$406,""),IF(N(_xlpm.t)=0,"",_xlpm.t))} -> 46326 | O18: Ongoing until term date; stop after final pay
A19: E0021 | B19: {=_xlfn.XLOOKUP($A19,TRIM(SUBSTITUTE('worker file'!$A$2:$A$406,_xlfn.UNICHAR(160)," ")),'worker file'!$L$2:$L$406,"Not found")} -> US Biweekly | C19: {=_xlfn.XLOOKUP($A19,TRIM(SUBSTITUTE('worker file'!$A$2:$A$406,_xlfn.UNICHAR(160)," ")),'worker file'!$D$2:$D$406,"Not found")} -> CA | D19: {=_xlfn.XLOOKUP($A19,TRIM(SUBSTITUTE('worker file'!$A$2:$A$406,_xlfn.UNICHAR(160)," ")),'worker file'!$Q$2:$Q$406,"Not found")} -> Active | E19: 401K_EE | F19: =_xlfn.XLOOKUP($E19,$A$5:$A$8,$B$5:$B$8,"") -> 401(k) Employee Deferral | G19: =_xlfn.XLOOKUP($E19,$A$5:$A$8,$D$5:$D$8,"") -> Pre-tax (exempt from FIT/SIT; subject to FICA) | H19: =_xlfn.XLOOKUP($E19,$A$5:$A$8,$E$5:$E$8,"") -> Percent | I19: 0.05 | J19: =IF($H19="Flat",_xlfn.XLOOKUP($E19,$A$5:$A$8,$F$5:$F$8,""),"") | K19: =_xlfn.XLOOKUP($E19,$A$5:$A$8,$G$5:$G$8,"") -> Gross pay | L19: =_xlfn.XLOOKUP($E19,$A$5:$A$8,$H$5:$H$8,"") -> Every pay period (ongoing) | M19: {=MAX(_xlfn.XLOOKUP($A19,TRIM(SUBSTITUTE('worker file'!$A$2:$A$406,_xlfn.UNICHAR(160)," ")),'worker file'!$M$2:$M$406,0),_xlfn.XLOOKUP($B19,TRIM('pay group & schedule'!$A$2:$A$6),'pay group & schedule'!$D$2:$D$6,0))} -> 46299 | N19: {=_xlfn.LET(_xlpm.t,_xlfn.XLOOKUP($A19,TRIM(SUBSTITUTE('worker file'!$A$2:$A$406,_xlfn.UNICHAR(160)," ")),'worker file'!$N$2:$N$406,""),IF(N(_xlpm.t)=0,"",_xlpm.t))}
A20: E0021 | B20: {=_xlfn.XLOOKUP($A20,TRIM(SUBSTITUTE('worker file'!$A$2:$A$406,_xlfn.UNICHAR(160)," ")),'worker file'!$L$2:$L$406,"Not found")} -> US Biweekly | C20: {=_xlfn.XLOOKUP($A20,TRIM(SUBSTITUTE('worker file'!$A$2:$A$406,_xlfn.UNICHAR(160)," ")),'worker file'!$D$2:$D$406,"Not found")} -> CA | D20: {=_xlfn.XLOOKUP($A20,TRIM(SUBSTITUTE('worker file'!$A$2:$A$406,_xlfn.UNICHAR(160)," ")),'worker file'!$Q$2:$Q$406,"Not found")} -> Active | E20: MED_EE | F20: =_xlfn.XLOOKUP($E20,$A$5:$A$8,$B$5:$B$8,"") -> Medical (Health) – Employee | G20: =_xlfn.XLOOKUP($E20,$A$5:$A$8,$D$5:$D$8,"") -> Pre-tax Section 125 (exempt from FIT/SIT/FICA) | H20: =_xlfn.XLOOKUP($E20,$A$5:$A$8,$E$5:$E$8,"") -> Flat | I20: =IF($H20="Percent",_xlfn.XLOOKUP($E20,$A$5:$A$8,$F$5:$F$8,""),"") | J20: =IF($H20="Flat",_xlfn.XLOOKUP($E20,$A$5:$A$8,$F$5:$F$8,""),"") -> 200 | K20: =_xlfn.XLOOKUP($E20,$A$5:$A$8,$G$5:$G$8,"") -> Per pay period | L20: =_xlfn.XLOOKUP($E20,$A$5:$A$8,$H$5:$H$8,"") -> Every pay period (ongoing) | M20: {=MAX(_xlfn.XLOOKUP($A20,TRIM(SUBSTITUTE('worker file'!$A$2:$A$406,_xlfn.UNICHAR(160)," ")),'worker file'!$M$2:$M$406,0),_xlfn.XLOOKUP($B20,TRIM('pay group & schedule'!$A$2:$A$6),'pay group & schedule'!$D$2:$D$6,0))} -> 46299 | N20: {=_xlfn.LET(_xlpm.t,_xlfn.XLOOKUP($A20,TRIM(SUBSTITUTE('worker file'!$A$2:$A$406,_xlfn.UNICHAR(160)," ")),'worker file'!$N$2:$N$406,""),IF(N(_xlpm.t)=0,"",_xlpm.t))}
A21: E0021 | B21: {=_xlfn.XLOOKUP($A21,TRIM(SUBSTITUTE('worker file'!$A$2:$A$406,_xlfn.UNICHAR(160)," ")),'worker file'!$L$2:$L$406,"Not found")} -> US Biweekly | C21: {=_xlfn.XLOOKUP($A21,TRIM(SUBSTITUTE('worker file'!$A$2:$A$406,_xlfn.UNICHAR(160)," ")),'worker file'!$D$2:$D$406,"Not found")} -> CA | D21: {=_xlfn.XLOOKUP($A21,TRIM(SUBSTITUTE('worker file'!$A$2:$A$406,_xlfn.UNICHAR(160)," ")),'worker file'!$Q$2:$Q$406,"Not found")} -> Active | E21: DEN_EE | F21: =_xlfn.XLOOKUP($E21,$A$5:$A$8,$B$5:$B$8,"") -> Dental – Employee | G21: =_xlfn.XLOOKUP($E21,$A$5:$A$8,$D$5:$D$8,"") -> Pre-tax Section 125 (exempt from FIT/SIT/FICA) | H21: =_xlfn.XLOOKUP($E21,$A$5:$A$8,$E$5:$E$8,"") -> Flat | I21: =IF($H21="Percent",_xlfn.XLOOKUP($E21,$A$5:$A$8,$F$5:$F$8,""),"") | J21: =IF($H21="Flat",_xlfn.XLOOKUP($E21,$A$5:$A$8,$F$5:$F$8,""),"") -> 44 | K21: =_xlfn.XLOOKUP($E21,$A$5:$A$8,$G$5:$G$8,"") -> Per pay period | L21: =_xlfn.XLOOKUP($E21,$A$5:$A$8,$H$5:$H$8,"") -> Every pay period (ongoing) | M21: {=MAX(_xlfn.XLOOKUP($A21,TRIM(SUBSTITUTE('worker file'!$A$2:$A$406,_xlfn.UNICHAR(160)," ")),'worker file'!$M$2:$M$406,0),_xlfn.XLOOKUP($B21,TRIM('pay group & schedule'!$A$2:$A$6),'pay group & schedule'!$D$2:$D$6,0))} -> 46299 | N21: {=_xlfn.LET(_xlpm.t,_xlfn.XLOOKUP($A21,TRIM(SUBSTITUTE('worker file'!$A$2:$A$406,_xlfn.UNICHAR(160)," ")),'worker file'!$N$2:$N$406,""),IF(N(_xlpm.t)=0,"",_xlpm.t))}
A22: E0021 | B22: {=_xlfn.XLOOKUP($A22,TRIM(SUBSTITUTE('worker file'!$A$2:$A$406,_xlfn.UNICHAR(160)," ")),'worker file'!$L$2:$L$406,"Not found")} -> US Biweekly | C22: {=_xlfn.XLOOKUP($A22,TRIM(SUBSTITUTE('worker file'!$A$2:$A$406,_xlfn.UNICHAR(160)," ")),'worker file'!$D$2:$D$406,"Not found")} -> CA | D22: {=_xlfn.XLOOKUP($A22,TRIM(SUBSTITUTE('worker file'!$A$2:$A$406,_xlfn.UNICHAR(160)," ")),'worker file'!$Q$2:$Q$406,"Not found")} -> Active | E22: VIS_EE | F22: =_xlfn.XLOOKUP($E22,$A$5:$A$8,$B$5:$B$8,"") -> Vision – Employee | G22: =_xlfn.XLOOKUP($E22,$A$5:$A$8,$D$5:$D$8,"") -> Pre-tax Section 125 (exempt from FIT/SIT/FICA) | H22: =_xlfn.XLOOKUP($E22,$A$5:$A$8,$E$5:$E$8,"") -> Flat | I22: =IF($H22="Percent",_xlfn.XLOOKUP($E22,$A$5:$A$8,$F$5:$F$8,""),"") | J22: =IF($H22="Flat",_xlfn.XLOOKUP($E22,$A$5:$A$8,$F$5:$F$8,""),"") -> 30 | K22: =_xlfn.XLOOKUP($E22,$A$5:$A$8,$G$5:$G$8,"") -> Per pay period | L22: =_xlfn.XLOOKUP($E22,$A$5:$A$8,$H$5:$H$8,"") -> Every pay period (ongoing) | M22: {=MAX(_xlfn.XLOOKUP($A22,TRIM(SUBSTITUTE('worker file'!$A$2:$A$406,_xlfn.UNICHAR(160)," ")),'worker file'!$M$2:$M$406,0),_xlfn.XLOOKUP($B22,TRIM('pay group & schedule'!$A$2:$A$6),'pay group & schedule'!$D$2:$D$6,0))} -> 46299 | N22: {=_xlfn.LET(_xlpm.t,_xlfn.XLOOKUP($A22,TRIM(SUBSTITUTE('worker file'!$A$2:$A$406,_xlfn.UNICHAR(160)," ")),'worker file'!$N$2:$N$406,""),IF(N(_xlpm.t)=0,"",_xlpm.t))}
A23: E0022 | B23: {=_xlfn.XLOOKUP($A23,TRIM(SUBSTITUTE('worker file'!$A$2:$A$406,_xlfn.UNICHAR(160)," ")),'worker file'!$L$2:$L$406,"Not found")} -> US Biweekly | C23: {=_xlfn.XLOOKUP($A23,TRIM(SUBSTITUTE('worker file'!$A$2:$A$406,_xlfn.UNICHAR(160)," ")),'worker file'!$D$2:$D$406,"Not found")} -> TX | D23: {=_xlfn.XLOOKUP($A23,TRIM(SUBSTITUTE('worker file'!$A$2:$A$406,_xlfn.UNICHAR(160)," ")),'worker file'!$Q$2:$Q$406,"Not found")} -> Active | E23: 401K_EE | F23: =_xlfn.XLOOKUP($E23,$A$5:$A$8,$B$5:$B$8,"") -> 401(k) Employee Deferral | G23: =_xlfn.XLOOKUP($E23,$A$5:$A$8,$D$5:$D$8,"") -> Pre-tax (exempt from FIT/SIT; subject to FICA) | H23: =_xlfn.XLOOKUP($E23,$A$5:$A$8,$E$5:$E$8,"") -> Percent | I23: 0.02 | J23: =IF($H23="Flat",_xlfn.XLOOKUP($E23,$A$5:$A$8,$F$5:$F$8,""),"") | K23: =_xlfn.XLOOKUP($E23,$A$5:$A$8,$G$5:$G$8,"") -> Gross pay | L23: =_xlfn.XLOOKUP($E23,$A$5:$A$8,$H$5:$H$8,"") -> Every pay period (ongoing) | M23: {=MAX(_xlfn.XLOOKUP($A23,TRIM(SUBSTITUTE('worker file'!$A$2:$A$406,_xlfn.UNICHAR(160)," ")),'worker file'!$M$2:$M$406,0),_xlfn.XLOOKUP($B23,TRIM('pay group & schedule'!$A$2:$A$6),'pay group & schedule'!$D$2:$D$6,0))} -> 46299 | N23: {=_xlfn.LET(_xlpm.t,_xlfn.XLOOKUP($A23,TRIM(SUBSTITUTE('worker file'!$A$2:$A$406,_xlfn.UNICHAR(160)," ")),'worker file'!$N$2:$N$406,""),IF(N(_xlpm.t)=0,"",_xlpm.t))}
A24: E0022 | B24: {=_xlfn.XLOOKUP($A24,TRIM(SUBSTITUTE('worker file'!$A$2:$A$406,_xlfn.UNICHAR(160)," ")),'worker file'!$L$2:$L$406,"Not found")} -> US Biweekly | C24: {=_xlfn.XLOOKUP($A24,TRIM(SUBSTITUTE('worker file'!$A$2:$A$406,_xlfn.UNICHAR(160)," ")),'worker file'!$D$2:$D$406,"Not found")} -> TX | D24: {=_xlfn.XLOOKUP($A24,TRIM(SUBSTITUTE('worker file'!$A$2:$A$406,_xlfn.UNICHAR(160)," ")),'worker file'!$Q$2:$Q$406,"Not found")} -> Active | E24: MED_EE | F24: =_xlfn.XLOOKUP($E24,$A$5:$A$8,$B$5:$B$8,"") -> Medical (Health) – Employee | G24: =_xlfn.XLOOKUP($E24,$A$5:$A$8,$D$5:$D$8,"") -> Pre-tax Section 125 (exempt from FIT/SIT/FICA) | H24: =_xlfn.XLOOKUP($E24,$A$5:$A$8,$E$5:$E$8,"") -> Flat | I24: =IF($H24="Percent",_xlfn.XLOOKUP($E24,$A$5:$A$8,$F$5:$F$8,""),"") | J24: =IF($H24="Flat",_xlfn.XLOOKUP($E24,$A$5:$A$8,$F$5:$F$8,""),"") -> 200 | K24: =_xlfn.XLOOKUP($E24,$A$5:$A$8,$G$5:$G$8,"") -> Per pay period | L24: =_xlfn.XLOOKUP($E24,$A$5:$A$8,$H$5:$H$8,"") -> Every pay period (ongoing) | M24: {=MAX(_xlfn.XLOOKUP($A24,TRIM(SUBSTITUTE('worker file'!$A$2:$A$406,_xlfn.UNICHAR(160)," ")),'worker file'!$M$2:$M$406,0),_xlfn.XLOOKUP($B24,TRIM('pay group & schedule'!$A$2:$A$6),'pay group & schedule'!$D$2:$D$6,0))} -> 46299 | N24: {=_xlfn.LET(_xlpm.t,_xlfn.XLOOKUP($A24,TRIM(SUBSTITUTE('worker file'!$A$2:$A$406,_xlfn.UNICHAR(160)," ")),'worker file'!$N$2:$N$406,""),IF(N(_xlpm.t)=0,"",_xlpm.t))}
A25: E0022 | B25: {=_xlfn.XLOOKUP($A25,TRIM(SUBSTITUTE('worker file'!$A$2:$A$406,_xlfn.UNICHAR(160)," ")),'worker file'!$L$2:$L$406,"Not found")} -> US Biweekly | C25: {=_xlfn.XLOOKUP($A25,TRIM(SUBSTITUTE('worker file'!$A$2:$A$406,_xlfn.UNICHAR(160)," ")),'worker file'!$D$2:$D$406,"Not found")} -> TX | D25: {=_xlfn.XLOOKUP($A25,TRIM(SUBSTITUTE('worker file'!$A$2:$A$406,_xlfn.UNICHAR(160)," ")),'worker file'!$Q$2:$Q$406,"Not found")} -> Active | E25: DEN_EE | F25: =_xlfn.XLOOKUP($E25,$A$5:$A$8,$B$5:$B$8,"") -> Dental – Employee | G25: =_xlfn.XLOOKUP($E25,$A$5:$A$8,$D$5:$D$8,"") -> Pre-tax Section 125 (exempt from FIT/SIT/FICA) | H25: =_xlfn.XLOOKUP($E25,$A$5:$A$8,$E$5:$E$8,"") -> Flat | I25: =IF($H25="Percent",_xlfn.XLOOKUP($E25,$A$5:$A$8,$F$5:$F$8,""),"") | J25: =IF($H25="Flat",_xlfn.XLOOKUP($E25,$A$5:$A$8,$F$5:$F$8,""),"") -> 44 | K25: =_xlfn.XLOOKUP($E25,$A$5:$A$8,$G$5:$G$8,"") -> Per pay period | L25: =_xlfn.XLOOKUP($E25,$A$5:$A$8,$H$5:$H$8,"") -> Every pay period (ongoing) | M25: {=MAX(_xlfn.XLOOKUP($A25,TRIM(SUBSTITUTE('worker file'!$A$2:$A$406,_xlfn.UNICHAR(160)," ")),'worker file'!$M$2:$M$406,0),_xlfn.XLOOKUP($B25,TRIM('pay group & schedule'!$A$2:$A$6),'pay group & schedule'!$D$2:$D$6,0))} -> 46299 | N25: {=_xlfn.LET(_xlpm.t,_xlfn.XLOOKUP($A25,TRIM(SUBSTITUTE('worker file'!$A$2:$A$406,_xlfn.UNICHAR(160)," ")),'worker file'!$N$2:$N$406,""),IF(N(_xlpm.t)=0,"",_xlpm.t))}
A26: E0022 | B26: {=_xlfn.XLOOKUP($A26,TRIM(SUBSTITUTE('worker file'!$A$2:$A$406,_xlfn.UNICHAR(160)," ")),'worker file'!$L$2:$L$406,"Not found")} -> US Biweekly | C26: {=_xlfn.XLOOKUP($A26,TRIM(SUBSTITUTE('worker file'!$A$2:$A$406,_xlfn.UNICHAR(160)," ")),'worker file'!$D$2:$D$406,"Not found")} -> TX | D26: {=_xlfn.XLOOKUP($A26,TRIM(SUBSTITUTE('worker file'!$A$2:$A$406,_xlfn.UNICHAR(160)," ")),'worker file'!$Q$2:$Q$406,"Not found")} -> Active | E26: VIS_EE | F26: =_xlfn.XLOOKUP($E26,$A$5:$A$8,$B$5:$B$8,"") -> Vision – Employee | G26: =_xlfn.XLOOKUP($E26,$A$5:$A$8,$D$5:$D$8,"") -> Pre-tax Section 125 (exempt from FIT/SIT/FICA) | H26: =_xlfn.XLOOKUP($E26,$A$5:$A$8,$E$5:$E$8,"") -> Flat | I26: =IF($H26="Percent",_xlfn.XLOOKUP($E26,$A$5:$A$8,$F$5:$F$8,""),"") | J26: =IF($H26="Flat",_xlfn.XLOOKUP($E26,$A$5:$A$8,$F$5:$F$8,""),"") -> 30 | K26: =_xlfn.XLOOKUP($E26,$A$5:$A$8,$G$5:$G$8,"") -> Per pay period | L26: =_xlfn.XLOOKUP($E26,$A$5:$A$8,$H$5:$H$8,"") -> Every pay period (ongoing) | M26: {=MAX(_xlfn.XLOOKUP($A26,TRIM(SUBSTITUTE('worker file'!$A$2:$A$406,_xlfn.UNICHAR(160)," ")),'worker file'!$M$2:$M$406,0),_xlfn.XLOOKUP($B26,TRIM('pay group & schedule'!$A$2:$A$6),'pay group & schedule'!$D$2:$D$6,0))} -> 46299 | N26: {=_xlfn.LET(_xlpm.t,_xlfn.XLOOKUP($A26,TRIM(SUBSTITUTE('worker file'!$A$2:$A$406,_xlfn.UNICHAR(160)," ")),'worker file'!$N$2:$N$406,""),IF(N(_xlpm.t)=0,"",_xlpm.t))}
